using FluentAssertions;
using System;
using System.Threading.Tasks;
using Xunit;

namespace CSharpFunctionalExtensions.Tests.ResultTests
{
    public class ResultTests
    {
        [Fact]
        public void Success_argument_is_null_Success_result_expected()
        {
            Result result = Result.Success<string>(null);

            result.IsSuccess.Should().BeTrue();
        }

        [Fact]
        public void Fail_argument_is_default_Fail_result_expected()
        {
            Result<string, int> result = Result.Failure<string, int>(0);

            result.IsFailure.Should().BeTrue();
        }

        [Fact]
        public void Fail_argument_is_not_default_Fail_result_expected()
        {
            Result<string, int> result = Result.Failure<string, int>(1);

            result.IsFailure.Should().BeTrue();
        }

        [Fact]
        public void Fail_argument_is_null_Exception_expected()
        {
            var exception = Record.Exception(() =>
                Result.Failure<string, string>(null));
            Assert.IsType<ArgumentNullException>(exception);
        }

        [Fact]
        public void Create_value_is_null_Success_result_expected()
        {
            Result result = Result.SuccessIf<string>(true, null, null);

            result.IsSuccess.Should().BeTrue();
        }

        [Fact]
        public void Create_error_is_null_Exception_expected()
        {
            var exception = Record.Exception(() =>
                Result.SuccessIf<string, string>(false, null, null));

            Assert.IsType<ArgumentNullException>(exception);
        }

        [Fact]
        public void Create_error_is_default_Failure_result_expected()
        {
            Result<bool, int> result = Result.SuccessIf<bool, int>(false, false, 0);

            result.IsFailure.Should().BeTrue();
            result.Error.Should().Be(0);
        }

        [Fact]
        public void Create_argument_is_true_Success_result_expected()
        {
            Result result = Result.SuccessIf(true, string.Empty);

            result.IsSuccess.Should().BeTrue();
        }

        [Fact]
        public void Create_argument_is_false_Failure_result_expected()
        {
            Result result = Result.SuccessIf(false, "simple result error");

            result.IsFailure.Should().BeTrue();
            result.Error.Should().Be("simple result error");
        }

        [Fact]
        public void Create_predicate_is_true_Success_result_expected()
        {
            Result result = Result.SuccessIf(() => true, string.Empty);

            result.IsSuccess.Should().BeTrue();
        }

        [Fact]
        public void Create_predicate_is_false_Failure_result_expected()
        {
            Result result = Result.SuccessIf(() => false, "predicate result error");

            result.IsFailure.Should().BeTrue();
            result.Error.Should().Be("predicate result error");
        }

        [Fact]
        public async Task Create_async_predicate_is_true_Success_result_expected()
        {
            Result result = await Result.SuccessIf(() => Task.FromResult(true), string.Empty);

            result.IsSuccess.Should().BeTrue();
        }

        [Fact]
        public async Task Create_async_predicate_is_false_Failure_result_expected()
        {
            Result result = await Result.SuccessIf(() => Task.FromResult(false), "predicate result error");

            result.IsFailure.Should().BeTrue();
            result.Error.Should().Be("predicate result error");
        }

        [Fact]
        public void CreateFailure_value_is_null_Success_result_expected()
        {
            Result result = Result.FailureIf<string>(false, null, null);

            result.IsSuccess.Should().BeTrue();
        }

        [Fact]
        public void CreateFailure_error_is_null_Exception_expected()
        {
            var exception = Record.Exception(() =>
                Result.FailureIf<string, string>(true, null, null));

            Assert.IsType<ArgumentNullException>(exception);
        }

        [Fact]
        public void CreateFailure_error_is_default_Failure_result_expected()
        {
            Result<bool, int> result = Result.FailureIf<bool, int>(true, false, 0);

            result.IsFailure.Should().BeTrue();
            result.Error.Should().Be(0);
        }

        [Fact]
        public void CreateFailure_argument_is_false_Success_result_expected()
        {
            Result result = Result.FailureIf(false, string.Empty);

            result.IsSuccess.Should().BeTrue();
        }

        [Fact]
        public void CreateFailure_argument_is_true_Failure_result_expected()
        {
            Result result = Result.FailureIf(true, "simple result error");

            result.IsFailure.Should().BeTrue();
            result.Error.Should().Be("simple result error");
        }

        [Fact]
        public void CreateFailure_predicate_is_false_Success_result_expected()
        {
            Result result = Result.FailureIf(() => false, string.Empty);

            result.IsSuccess.Should().BeTrue();
        }

        [Fact]
        public void CreateFailure_predicate_is_true_Failure_result_expected()
        {
            Result result = Result.FailureIf(() => true, "predicate result error");

            result.IsFailure.Should().BeTrue();
            result.Error.Should().Be("predicate result error");
        }

        [Fact]
        public async Task CreateFailure_async_predicate_is_false_Success_result_expected()
        {
            Result result = await Result.FailureIf(() => Task.FromResult(false), string.Empty);

            result.IsSuccess.Should().BeTrue();
        }

        [Fact]
        public async Task CreateFailure_async_predicate_is_true_Failure_result_expected()
        {
            Result result = await Result.FailureIf(() => Task.FromResult(true), "predicate result error");

            result.IsFailure.Should().BeTrue();
            result.Error.Should().Be("predicate result error");
        }

        [Fact]
        public void Create_generic_argument_is_true_Success_result_expected()
        {
            byte val = 7;
            Result<byte> result = Result.SuccessIf(true, val, string.Empty);

            result.IsSuccess.Should().BeTrue();
            result.Value.Should().Be(val);
        }

        [Fact]
        public void Create_generic_argument_is_false_Failure_result_expected()
        {
            double val = .56;
            Result<double> result = Result.SuccessIf(false, val, "simple result error");

            result.IsFailure.Should().BeTrue();
            result.Error.Should().Be("simple result error");
        }

        [Fact]
        public void Create_generic_predicate_is_true_Success_result_expected()
        {
            DateTime val = new DateTime(2000, 1, 1);

            Result<DateTime> result = Result.SuccessIf(() => true, val, string.Empty);

            result.IsSuccess.Should().BeTrue();
            result.Value.Should().Be(val);
        }

        [Fact]
        public void Create_generic_predicate_is_false_Failure_result_expected()
        {
            string val = "string value";

            Result<string> result = Result.SuccessIf(() => false, val, "predicate result error");

            result.IsFailure.Should().BeTrue();
            result.Error.Should().Be("predicate result error");
        }

        [Fact]
        public async Task Create_generic_async_predicate_is_true_Success_result_expected()
        {
            int val = 42;

            Result<int> result = await Result.SuccessIf(() => Task.FromResult(true), val, string.Empty);

            result.IsSuccess.Should().BeTrue();
            result.Value.Should().Be(val);
        }

        [Fact]
        public async Task Create_generic_async_predicate_is_false_Failure_result_expected()
        {
            bool val = true;

            Result<bool> result = await Result.SuccessIf(() => Task.FromResult(false), val, "predicate result error");

            result.IsFailure.Should().BeTrue();
            result.Error.Should().Be("predicate result error");
        }


        [Fact]
        public void Create_error_generic_argument_is_true_Success_result_expected()
        {
            byte val = 7;
            Result<byte, Error> result = Result.SuccessIf(true, val, new Error());

            result.IsSuccess.Should().BeTrue();
            result.Value.Should().Be(val);
        }

        [Fact]
        public void Create_error_generic_argument_is_false_Failure_result_expected()
        {
            double val = .56;
            var error = new Error();

            Result<double, Error> result = Result.SuccessIf(false, val, error);

            result.IsFailure.Should().BeTrue();
            result.Error.Should().Be(error);
        }

        [Fact]
        public void Create_error_generic_predicate_is_true_Success_result_expected()
        {
            DateTime val = new DateTime(2000, 1, 1);

            Result<DateTime, Error> result = Result.SuccessIf(() => true, val, new Error());

            result.IsSuccess.Should().BeTrue();
            result.Value.Should().Be(val);
        }

        [Fact]
        public void Create_error_generic_predicate_is_false_Failure_result_expected()
        {
            string val = "string value";
            var error = new Error();

            Result<string, Error> result = Result.SuccessIf(() => false, val, error);

            result.IsFailure.Should().BeTrue();
            result.Error.Should().Be(error);
        }

        [Fact]
        public async Task Create_error_generic_async_predicate_is_true_Success_result_expected()
        {
            int val = 42;

            Result<int, Error> result = await Result.SuccessIf(() => Task.FromResult(true), val, new Error());

            result.IsSuccess.Should().BeTrue();
            result.Value.Should().Be(val);
        }

        [Fact]
        public async Task Create_error_generic_async_predicate_is_false_Failure_result_expected()
        {
            bool val = true;
            var error = new Error();

            Result<bool, Error> result = await Result.SuccessIf(() => Task.FromResult(false), val, error);

            result.IsFailure.Should().BeTrue();
            result.Error.Should().Be(error);
        }

        [Fact]
        public void CreateFailure_generic_argument_is_false_Success_result_expected()
        {
            byte val = 7;
            Result<byte> result = Result.FailureIf(false, val, string.Empty);

            result.IsSuccess.Should().BeTrue();
            result.Value.Should().Be(val);
        }

        [Fact]
        public void CreateFailure_generic_argument_is_true_Failure_result_expected()
        {
            double val = .56;
            Result<double> result = Result.FailureIf(true, val, "simple result error");

            result.IsFailure.Should().BeTrue();
            result.Error.Should().Be("simple result error");
        }

        [Fact]
        public void CreateFailure_generic_predicate_is_false_Success_result_expected()
        {
            DateTime val = new DateTime(2000, 1, 1);

            Result<DateTime> result = Result.FailureIf(() => false, val, string.Empty);

            result.IsSuccess.Should().BeTrue();
            result.Value.Should().Be(val);
        }

        [Fact]
        public void CreateFailure_generic_predicate_is_true_Failure_result_expected()
        {
            string val = "string value";

            Result<string> result = Result.FailureIf(() => true, val, "predicate result error");

            result.IsFailure.Should().BeTrue();
            result.Error.Should().Be("predicate result error");
        }

        [Fact]
        public async Task CreateFailure_generic_async_predicate_is_false_Success_result_expected()
        {
            int val = 42;

            Result<int> result = await Result.FailureIf(() => Task.FromResult(false), val, string.Empty);

            result.IsSuccess.Should().BeTrue();
            result.Value.Should().Be(val);
        }

        [Fact]
        public async Task CreateFailure_generic_async_predicate_is_true_Failure_result_expected()
        {
            bool val = true;

            Result<bool> result = await Result.FailureIf(() => Task.FromResult(true), val, "predicate result error");

            result.IsFailure.Should().BeTrue();
            result.Error.Should().Be("predicate result error");
        }


        [Fact]
        public void CreateFailure_error_generic_argument_is_false_Success_result_expected()
        {
            byte val = 7;
            Result<byte, Error> result = Result.FailureIf(false, val, new Error());

            result.IsSuccess.Should().BeTrue();
            result.Value.Should().Be(val);
        }

        [Fact]
        public void CreateFailure_error_generic_argument_is_true_Failure_result_expected()
        {
            double val = .56;
            var error = new Error();

            Result<double, Error> result = Result.FailureIf(true, val, error);

            result.IsFailure.Should().BeTrue();
            result.Error.Should().Be(error);
        }

        [Fact]
        public void CreateFailure_error_generic_predicate_is_false_Success_result_expected()
        {
            DateTime val = new DateTime(2000, 1, 1);

            Result<DateTime, Error> result = Result.FailureIf(() => false, val, new Error());

            result.IsSuccess.Should().BeTrue();
            result.Value.Should().Be(val);
        }

        [Fact]
        public void CreateFailure_error_generic_predicate_is_true_Failure_result_expected()
        {
            string val = "string value";
            var error = new Error();

            Result<string, Error> result = Result.FailureIf(() => true, val, error);

            result.IsFailure.Should().BeTrue();
            result.Error.Should().Be(error);
        }

        [Fact]
        public async Task CreateFailure_error_generic_async_predicate_is_false_Success_result_expected()
        {
            int val = 42;

            Result<int, Error> result = await Result.FailureIf(() => Task.FromResult(false), val, new Error());

            result.IsSuccess.Should().BeTrue();
            result.Value.Should().Be(val);
        }

        [Fact]
        public async Task CreateFailure_error_generic_async_predicate_is_true_Failure_result_expected()
        {
            bool val = true;
            var error = new Error();

            Result<bool, Error> result = await Result.FailureIf(() => Task.FromResult(true), val, error);

            result.IsFailure.Should().BeTrue();
            result.Error.Should().Be(error);
        }

        [Fact]
        public void Can_work_with_nullable_sructs()
        {
            Result<DateTime?> result = Result.Success((DateTime?)null);

            result.IsSuccess.Should().BeTrue();
            result.Value.Should().Be(null);
        }

        [Fact]
        public void Can_work_with_maybe_of_struct()
        {
            Maybe<DateTime> maybe = Maybe<DateTime>.None;

            Result<Maybe<DateTime>> result = Result.Success(maybe);

            result.IsSuccess.Should().BeTrue();
            result.Value.Should().Be(Maybe<DateTime>.None);
        }

        [Fact]
        public void Can_work_with_maybe_of_ref_type()
        {
            Maybe<string> maybe = Maybe<string>.None;

            Result<Maybe<string>> result = Result.Success(maybe);

            result.IsSuccess.Should().BeTrue();
            result.Value.Should().Be(Maybe<string>.None);
        }

        [Fact]
        public void Try_execute_function_success_without_error_handler_function_result_expected()
        {
            Func<int> func = () => 5;

            var result = Result.Try(func);

            result.IsSuccess.Should().BeTrue();
            result.Value.Should().Be(5);
        }

        [Fact]
        public void Try_execute_function_failed_without_error_handler_failed_result_expected()
        {
            Func<int> func = () => throw new Exception("func error");

            var result = Result.Try(func);

            result.IsFailure.Should().BeTrue();
            result.Error.Should().Be("func error");
        }

        [Fact]
        public void Try_execute_function_failed_with_error_handler_failed_result_expected()
        {
            Func<int> func = () => throw new Exception("func error");
            Func<Exception, string> handler = exc => "execute error";

            var result = Result.Try(func, handler);

            result.IsFailure.Should().BeTrue();
            result.Error.Should().Be("execute error");
        }

        [Fact]
        public void Try_execute_action_success_without_error_handler_function_result_expected()
        {
            Action action = () => { };

            var result = Result.Try(action);

            result.IsSuccess.Should().BeTrue();
        }

        [Fact]
        public void Try_execute_action_failed_without_error_handler_failed_result_expected()
        {
            Action action = () => throw new Exception("func error");

            var result = Result.Try(action);

            result.IsFailure.Should().BeTrue();
            result.Error.Should().Be("func error");
        }

        [Fact]
        public void Try_execute_action_failed_with_error_handler_failed_result_expected()
        {
            Action action = () => throw new Exception("func error");
            Func<Exception, string> handler = exc => "execute error";

            var result = Result.Try(action, handler);

            result.IsFailure.Should().BeTrue();
            result.Error.Should().Be("execute error");
        }

        [Fact]
        public async Task Try_execute_async_action_success_without_error_handler_function_result_expected()
        {
            Func<Task> action = () => Task.CompletedTask;

            var result = await Result.Try(action);

            result.IsSuccess.Should().BeTrue();
        }

        [Fact]
        public async Task Try_execute_async_action_failed_without_error_handler_failed_result_expected()
        {
            Func<Task> action = () => Task.FromException(new Exception("func error"));

            var result = await Result.Try(action);

            result.IsFailure.Should().BeTrue();
            result.Error.Should().Be("func error");
        }

        [Fact]
        public async Task Try_execute_async_action_failed_with_error_handler_failed_result_expected()
        {
            Func<Task> action = () => Task.FromException(new Exception("func error"));
            Func<Exception, string> handler = exc => "execute error";

            var result = await Result.Try(action, handler);

            result.IsFailure.Should().BeTrue();
            result.Error.Should().Be("execute error");
        }

        [Fact]
        public void Try_with_error_execute_function_success_without_error_success_result_expected()
        {
            Func<string> func = () => "execution result";
            var error = new Error();

            var result = Result.Try(func, exc => error);

            result.IsSuccess.Should().BeTrue();
            result.Value.Should().Be("execution result");
        }

        [Fact]
        public void Try_with_error_execute_function_failed_with_error_handler_failed_result_expected()
        {
            Func<int> func = () => throw new Exception("func error");
            var error = new Error();

            var result = Result.Try(func, exc => error);

            result.IsFailure.Should().BeTrue();
            result.Error.Should().Be(error);
        }

        [Fact]
        public async Task Try_async_execute_function_success_without_error_handler_function_result_expected()
        {
            Func<Task<int>> func = () => Task.FromResult(5);

            var result = await Result.Try(func);

            result.IsSuccess.Should().BeTrue();
            result.Value.Should().Be(5);
        }

        [Fact]
        public async Task Try_async_execute_function_failed_without_error_handler_failed_result_expected()
        {
            Func<Task<int>> func = () => Task.FromException<int>(new Exception("func error"));

            var result = await Result.Try(func);

            result.IsFailure.Should().BeTrue();
            result.Error.Should().Be("func error");
        }

        [Fact]
        public async Task Try_async_execute_function_failed_with_error_handler_failed_result_expected()
        {
            Func<Task<int>> func = () => Task.FromException<int>(new Exception("func error"));
            Func<Exception, string> handler = exc => "execute error";

            var result = await Result.Try(func, handler);

            result.IsFailure.Should().BeTrue();
            result.Error.Should().Be("execute error");
        }

        [Fact]
        public async Task Try_async_with_error_execute_function_success_without_error_success_result_expected()
        {
            Func<Task<string>> func = () => Task.FromResult("execution result");

            var result = await Result.Try(func, exc => new Error());

            result.IsSuccess.Should().BeTrue();
            result.Value.Should().Be("execution result");
        }

        [Fact]
        public async Task Try_async_with_error_execute_function_failed_with_error_handler_failed_result_expected()
        {
            Func<Task<DateTime>> func = () => Task.FromException<DateTime>(new Exception("func error"));
            var error = new Error();

            var result = await Result.Try(func, exc => error);

            result.IsFailure.Should().BeTrue();
            result.Error.Should().Be(error);
        }

        private class Error
        {
        }

        [Fact]
        public async Task When_Asynchronous_Continuation_Passed_To_On_Success_Try_Then_Needs_To_Be_Handled_As_Awaitable() {
            var content = "my key";
            var result = Result.Success<string>(content);

            await result
                .OnSuccessTry(async (key) => {
                    await Task.Delay(10);
                    var task = Task.FromResult(key);
                    var k = await task;
                    k.Should().Be(content);
                });
        }

        [Fact]
        public async Task When_Asynchronous_Continuation_Passed_With_Typed_Error_To_On_Success_Try_Then_Needs_To_Be_Handled_As_Awaitable()
        {
            var content = "my key";
            var result = Result.Success<string, Error>(content);

            await result
                .OnSuccessTry(async (key) =>
                {
                    await Task.Delay(10);
                    var task = Task.FromResult(key);
                    var k = await task;
                    k.Should().Be(content);
                });
        }
    }
}